// Copyright (c) Microsoft. All rights reserved.
// Licensed under the MIT license. See LICENSE file in the project root for full license information.

using System.Collections.Generic;
using System.Diagnostics;
using System.Threading;
using System.Threading.Tasks;
using Xunit;

namespace System.Linq.Parallel.Tests
{
    // a key part of cancellation testing is 'promptness'.  Those tests appear in pfxperfunittests.
    // the tests here are only regarding basic API correctness and sanity checking.
    public static class WithCancellationTests
    {
        [Fact]
        public static void PreCanceledToken_ForAll()
        {
            OperationCanceledException caughtException = null;
            var cs = new CancellationTokenSource();
            cs.Cancel();

            IEnumerable<int> throwOnFirstEnumerable = Enumerables<int>.ThrowOnEnumeration();

            try
            {
                throwOnFirstEnumerable
                    .AsParallel()
                    .WithCancellation(cs.Token)
                    .ForAll((x) => { Debug.WriteLine(x.ToString()); });
            }
            catch (OperationCanceledException ex)
            {
                caughtException = ex;
            }

            Assert.NotNull(caughtException);
            Assert.Equal(cs.Token, caughtException.CancellationToken);
        }

        [Fact]
        public static void PreCanceledToken_SimpleEnumerator()
        {
            OperationCanceledException caughtException = null;
            var cs = new CancellationTokenSource();
            cs.Cancel();

            IEnumerable<int> throwOnFirstEnumerable = Enumerables<int>.ThrowOnEnumeration();

            try
            {
                var query = throwOnFirstEnumerable
                    .AsParallel()
                    .WithCancellation(cs.Token);

                foreach (var item in query)
                {
                }
            }
            catch (OperationCanceledException ex)
            {
                caughtException = ex;
            }

            Assert.NotNull(caughtException);
            Assert.Equal(cs.Token, caughtException.CancellationToken);
        }

        [Fact]
        public static void MultiplesWithCancellationIsIllegal()
        {
            InvalidOperationException caughtException = null;
            try
            {
                CancellationTokenSource cs = new CancellationTokenSource();
                CancellationToken ct = cs.Token;
                var query = Enumerable.Range(1, 10).AsParallel().WithDegreeOfParallelism(2).WithDegreeOfParallelism(2);
                query.ToArray();
            }
            catch (InvalidOperationException ex)
            {
                caughtException = ex;
                //Program.TestHarness.Log("IOE caught. message = " + ex.Message);
            }

            Assert.NotNull(caughtException);
        }

        [Fact]
        public static void CTT_Sorting_ToArray()
        {
            int size = 10000;
            CancellationTokenSource tokenSource = new CancellationTokenSource();

            OperationCanceledException caughtException = null;
            try
            {
                Enumerable.Range(1, size).AsParallel()
                        .WithCancellation(tokenSource.Token)
                        .Select(i =>
                        {
                            tokenSource.Cancel();
                            return i;
                        })
                        .ToArray();
            }
            catch (OperationCanceledException ex)
            {
                caughtException = ex;
            }

            Assert.NotNull(caughtException);
            Assert.Equal(tokenSource.Token, caughtException.CancellationToken);
        }

        /// <summary>
        ///
        /// [Regression Test]
        ///   This issue occurred because the QuerySettings structure was not being deep-cloned during
        ///   query-opening.  As a result, the concurrent inner-enumerators (for the RHS operators)
        ///   that occur in SelectMany were sharing CancellationState that they should not have.
        ///   The result was that enumerators could falsely believe they had been canceled when
        ///   another inner-enumerator was disposed.
        ///
        ///   Note: the failure was intermittent.  this test would fail about 1 in 2 times on mikelid1 (4-core).
        /// </summary>
        /// <returns></returns>
        [Fact]
        public static void CloningQuerySettingsForSelectMany()
        {
            var plinq_src = ParallelEnumerable.Range(0, 1999).AsParallel();
            Exception caughtException = null;

            try
            {
                var inner = ParallelEnumerable.Range(0, 20).AsParallel().Select(_item => _item);
                var output = plinq_src
                    .SelectMany(
                        _x => inner,
                        (_x, _y) => _x
                    )
                    .ToArray();
            }
            catch (Exception ex)
            {
                caughtException = ex;
            }

            Assert.Null(caughtException);
        }

        // [Regression Test]
        // Use of the async channel can block both the consumer and producer threads.. before the cancellation work
        // these had no means of being awoken.
        //
        // However, only the producers need to wake up on cancellation as the consumer
        // will wake up once all the producers have gone away (via AsynchronousOneToOneChannel.SetDone())
        //
        // To specifically verify this test, we want to know that the Async channels were blocked in TryEnqueChunk before Dispose() is called
        //  -> this was verified manually, but is not simple to automate
        [Fact]
        [OuterLoop]  // explicit timeouts / delays
        public static void ChannelCancellation_ProducerBlocked()
        {
            Debug.WriteLine("PlinqCancellationTests.ChannelCancellation_ProducerBlocked()");

            Debug.WriteLine("        Query running (should be few seconds max)..");
            var query1 = Enumerable.Range(0, 100000000)  //provide 100million elements to ensure all the cores get >64K ints. Good up to 1600cores
                .AsParallel()
                .Select(x => x);
            var enumerator1 = query1.GetEnumerator();
            enumerator1.MoveNext();
            Task.Delay(1000).Wait();
            enumerator1.MoveNext();
            enumerator1.Dispose(); //can potentially hang

            Debug.WriteLine("        Done (success).");
        }

        /// <summary>
        /// [Regression Test]
        ///   This issue occurred because aggregations like Sum or Average would incorrectly
        ///   wrap OperationCanceledException with AggregateException.
        /// </summary>
        [Fact]
        public static void AggregatesShouldntWrapOCE()
        {
            var cs = new CancellationTokenSource();
            cs.Cancel();

            // Expect OperationCanceledException rather than AggregateException or something else
            try
            {
                Enumerable.Range(0, 1000).AsParallel().WithCancellation(cs.Token).Sum(x => x);
            }
            catch (OperationCanceledException)
            {
                return;
            }
            catch (Exception e)
            {
                Assert.True(false, string.Format("PlinqCancellationTests.AggregatesShouldntWrapOCE:  > Failed: got {0}, expected OperationCanceledException", e.GetType().ToString()));
            }

            Assert.True(false, string.Format("PlinqCancellationTests.AggregatesShouldntWrapOCE:  > Failed: no exception occurred, expected OperationCanceledException"));
        }

        // Plinq suppresses OCE(externalCT) occurring in worker threads and then throws a single OCE(ct)
        // if a manual OCE(ct) is thrown but ct is not canceled, Plinq should not suppress it, else things
        // get confusing...
        // ONLY an OCE(ct) for ct.IsCancellationRequested=true is co-operative cancellation
        [Fact]
        public static void OnlySuppressOCEifCTCanceled()
        {
            AggregateException caughtException = null;
            CancellationTokenSource cts = new CancellationTokenSource();
            CancellationToken externalToken = cts.Token;
            try
            {
                Enumerable.Range(1, 10).AsParallel()
                    .WithCancellation(externalToken)
                    .Select(
                      x =>
                      {
                          if (x % 2 == 0) throw new OperationCanceledException(externalToken);
                          return x;
                      }
                    )
                 .ToArray();
            }
            catch (AggregateException ae)
            {
                caughtException = ae;
            }

            Assert.NotNull(caughtException);
        }

        // a specific repro where inner queries would see an ODE on the merged cancellation token source
        // when the implementation involved disposing and recreating the token on each worker thread
        [Fact]
        public static void Cancellation_ODEIssue()
        {
            AggregateException caughtException = null;
            try
            {
                Enumerable.Range(0, 1999).ToArray()
                .AsParallel().AsUnordered()
                .WithExecutionMode(ParallelExecutionMode.ForceParallelism)
                .Zip<int, int, int>(
                    Enumerable.Range(1000, 20).Select<int, int>(_item => (int)_item).AsParallel().AsUnordered(),
                    (first, second) => { throw new OperationCanceledException(); })
               .ForAll(x => { });
            }
            catch (AggregateException ae)
            {
                caughtException = ae;
            }

            //the failure was an ODE coming out due to an ephemeral disposed merged cancellation token source.
            Assert.True(caughtException != null,
                                              "Cancellation_ODEIssue:  We expect an aggregate exception with OCEs in it.");
        }

        [Fact]
        [OuterLoop] // explicit timeouts / delays
        public static void CancellationSequentialWhere()
        {
            IEnumerable<int> src = Enumerable.Repeat(0, int.MaxValue);
            CancellationTokenSource tokenSrc = new CancellationTokenSource();

            var q = src.AsParallel().WithCancellation(tokenSrc.Token).Where(x => false).TakeWhile(x => true);

            Task task = Task.Run(
                () =>
                {
                    try
                    {
                        foreach (var x in q) { }

                        Assert.True(false, string.Format("PlinqCancellationTests.CancellationSequentialWhere:  > Failed: OperationCanceledException was not caught."));
                    }
                    catch (OperationCanceledException oce)
                    {
                        if (oce.CancellationToken != tokenSrc.Token)
                        {
                            Assert.True(false, string.Format("PlinqCancellationTests.CancellationSequentialWhere:  > Failed: Wrong cancellation token."));
                        }
                    }
                }
            );

            // We wait for 100 ms. If we canceled the token source immediately, the cancellation
            // would occur at the query opening time. The goal of this test is to test cancellation
            // at query execution time.
            Task.Delay(100).Wait();
            //Thread.Sleep(100);

            tokenSrc.Cancel();
            task.Wait();
        }

        [Fact]
        [OuterLoop] // explicit timeouts / delays
        public static void CancellationSequentialElementAt()
        {
            IEnumerable<int> src = Enumerable.Repeat(0, int.MaxValue);
            CancellationTokenSource tokenSrc = new CancellationTokenSource();

            Task task = Task.Run(
                () =>
                {
                    try
                    {
                        int res = src.AsParallel()
                            .WithCancellation(tokenSrc.Token)
                            .Where(x => true)
                            .TakeWhile(x => true)
                            .ElementAt(int.MaxValue - 1);

                        Assert.True(false, string.Format("PlinqCancellationTests.CancellationSequentialElementAt:  > Failed: OperationCanceledException was not caught."));
                    }
                    catch (OperationCanceledException oce)
                    {
                        Assert.Equal(oce.CancellationToken, tokenSrc.Token);
                    }
                }
            );

            // We wait for 100 ms. If we canceled the token source immediately, the cancellation
            // would occur at the query opening time. The goal of this test is to test cancellation
            // at query execution time.
            Task.Delay(100).Wait();

            tokenSrc.Cancel();
            task.Wait();
        }

        [Fact]
        [OuterLoop]  // explicit timeouts / delays
        public static void CancellationSequentialDistinct()
        {
            IEnumerable<int> src = Enumerable.Repeat(0, int.MaxValue);
            CancellationTokenSource tokenSrc = new CancellationTokenSource();

            Task task = Task.Run(
                () =>
                {
                    try
                    {
                        var q = src.AsParallel()
                            .WithCancellation(tokenSrc.Token)
                            .Distinct()
                            .TakeWhile(x => true);

                        foreach (var x in q) { }

                        Assert.True(false, string.Format("PlinqCancellationTests.CancellationSequentialDistinct:  > Failed: OperationCanceledException was not caught."));
                    }
                    catch (OperationCanceledException oce)
                    {
                        Assert.Equal(oce.CancellationToken, tokenSrc.Token);
                    }
                }
            );

            // We wait for 100 ms. If we canceled the token source immediately, the cancellation
            // would occur at the query opening time. The goal of this test is to test cancellation
            // at query execution time.
            Task.Delay(100).Wait();

            tokenSrc.Cancel();
            task.Wait();
        }

        // Regression test for an issue causing ODE if a queryEnumerator is disposed before moveNext is called.
        [Fact]
        public static void ImmediateDispose()
        {
            var queryEnumerator = Enumerable.Range(1, 10).AsParallel().Select(x => x).GetEnumerator();
            queryEnumerator.Dispose();
        }

        // REPRO 1 -- cancellation
        [Fact]
        public static void SetOperationsThrowAggregateOnCancelOrDispose_1()
        {
            CancellationTokenSource cs = new CancellationTokenSource();
            var plinq_src =
                Enumerable.Range(0, 5000000).Select(x =>
                {
                    cs.Cancel();
                    return x;
                });

            try
            {
                var plinq = plinq_src
                    .AsParallel().WithCancellation(cs.Token)
                    .WithDegreeOfParallelism(1)
                    .Union(Enumerable.Range(0, 10).AsParallel());

                var walker = plinq.GetEnumerator();
                while (walker.MoveNext())
                {
                    var item = walker.Current;
                }
                Assert.True(false, string.Format("PlinqCancellationTests.SetOperationsThrowAggregateOnCancelOrDispose_1:  OperationCanceledException was expected, but no exception occurred."));
            }
            catch (OperationCanceledException)
            {
                //This is expected.
            }
            catch (Exception e)
            {
                Assert.True(false, string.Format("PlinqCancellationTests.SetOperationsThrowAggregateOnCancelOrDispose_1:  OperationCanceledException was expected, but a different exception occurred.  " + e.ToString()));
            }
        }

        // throwing a fake OCE(ct) when the ct isn't canceled should produce an AggregateException.
        [Fact]
        public static void SetOperationsThrowAggregateOnCancelOrDispose_2()
        {
            try
            {
                CancellationTokenSource cs = new CancellationTokenSource();
                var plinq = Enumerable.Range(0, 50)
                    .AsParallel().WithCancellation(cs.Token)
                    .WithDegreeOfParallelism(1)
                    .Union(Enumerable.Range(0, 10).AsParallel().Select<int, int>(x => { throw new OperationCanceledException(cs.Token); }));

                var walker = plinq.GetEnumerator();
                while (walker.MoveNext())
                {
                }
                Assert.True(false, string.Format("PlinqCancellationTests.SetOperationsThrowAggregateOnCancelOrDispose_2:  failed.  AggregateException was expected, but no exception occurred."));
            }
            catch (AggregateException)
            {
                // expected
            }
            catch (Exception e)
            {
                Assert.True(false, string.Format("PlinqCancellationTests.SetOperationsThrowAggregateOnCancelOrDispose_2.  failed.  AggregateException was expected, but some other exception occurred." + e.ToString()));
            }
        }

        // Changes made to hash-partitioning (April'09) lost the cancellation checks during the
        // main repartitioning loop (matrix building).
        [Fact]
        public static void HashPartitioningCancellation()
        {
            OperationCanceledException caughtException = null;

            CancellationTokenSource cs = new CancellationTokenSource();

            //Without ordering
            var queryUnordered = Enumerable.Range(0, int.MaxValue)
                .Select(x => { if (x == 0) cs.Cancel(); return x; })
                .AsParallel()
                .WithCancellation(cs.Token)
                .Intersect(Enumerable.Range(0, 1000000).AsParallel());

            try
            {
                foreach (var item in queryUnordered)
                {
                }
            }
            catch (OperationCanceledException oce)
            {
                caughtException = oce;
            }

            Assert.NotNull(caughtException);

            caughtException = null;

            //With ordering
            var queryOrdered = Enumerable.Range(0, int.MaxValue)
               .Select(x => { if (x == 0) cs.Cancel(); return x; })
               .AsParallel().AsOrdered()
               .WithCancellation(cs.Token)
               .Intersect(Enumerable.Range(0, 1000000).AsParallel());

            try
            {
                foreach (var item in queryOrdered)
                {
                }
            }
            catch (OperationCanceledException oce)
            {
                caughtException = oce;
            }

            Assert.NotNull(caughtException);
        }

        // If a query is cancelled and immediately disposed, the dispose should not throw an OCE.
        [Fact]
        public static void CancelThenDispose()
        {
            try
            {
                CancellationTokenSource cancel = new CancellationTokenSource();
                var q = ParallelEnumerable.Range(0, 1000).WithCancellation(cancel.Token).Select(x => x);
                IEnumerator<int> e = q.GetEnumerator();
                e.MoveNext();

                cancel.Cancel();
                e.Dispose();
            }
            catch (Exception e)
            {
                Assert.True(false, string.Format("PlinqCancellationTests.CancelThenDispose:  > Failed. Expected no exception, got " + e.GetType()));
            }
        }

        [Fact]
        public static void DontDoWorkIfTokenAlreadyCanceled()
        {
            OperationCanceledException oce = null;

            CancellationTokenSource cs = new CancellationTokenSource();
            var query = Enumerable.Range(0, 100000000)
            .Select(x =>
            {
                if (x > 0) // to avoid the "Error:unreachable code detected"
                    throw new ArgumentException("User-delegate exception.");
                return x;
            })
            .AsParallel()
            .WithCancellation(cs.Token)
            .Select(x => x);

            cs.Cancel();
            try
            {
                foreach (var item in query) //We expect an OperationCancelledException during the MoveNext
                {
                }
            }
            catch (OperationCanceledException ex)
            {
                oce = ex;
            }

            Assert.NotNull(oce);
        }
    }
}
